Workbook

Sheet 195 States
A1: Country | B1: Head of state | C1: Head of government | D1: Ideological family | E1: Variant code | F1: Variant | G1: Secondary family | H1: Full code | I1: Decontested form (this government) | J1: Thin-centred components | K1: Adjacent concepts / regime context | L1: Policy approach / key domains | M1: Previous code (conservatism-only scheme)
A2: Afghanistan | B2: Hibatullah Akhundzada | C2: Hasan Akhund | D2: Religious-political ideology | E2: RE | F2: Theocracy | H2: RE | I2: Islamist theocracy (Taliban emirate) | K2: Authoritarian rule | L2: Tradition/religion; sharia; authority/order; restrictive social policy; state-controlled economy; restrictive migration; security-first foreign policy | M2: T — traditionalist-authoritarian
A3: Albania | B3: Bajram Begaj | C3: Edi Rama | D3: Socialism | E3: S | F3: Social democracy | G3: Liberalism | H3: S/LIB | I3: Third Way social democracy (Socialist Party) | L3: EU integration; social-democratic governance; market economy; gradual institutional reform; pragmatic migration policy | M3: L/C — centre-left
A4: Algeria | B4: Abdelmadjid Tebboune | C4: Sifi Ghrieb | D4: Socialism | E4: S+ | F4: Left-nationalist / left-populist socialism | H4: S+ | I4: Post-revolutionary state socialism and nationalism (FLN legacy) | J4: Nationalism | K4: Authoritarian rule | L4: National sovereignty; state role in economy; social conservatism; controlled migration; hydrocarbons; security/state continuity | M4: T — nationalist-authoritarian
A5: Andorra | B5: Josep-Lluís Serrano / Emmanuel Macron | C5: Xavier Espot | D5: Conservatism | E5: C | F5: Conservatism | G5: Liberalism | H5: C/LIB | I5: Liberal conservatism / Christian democracy | L5: Small-state market economy; institutional continuity; Catholic heritage; open European orientation | M5: C/L — liberal-conservative hybrid
A6: Angola | B6: João Lourenço | C6: João Lourenço | D6: Traditionalist-authoritarian | E6: T | F6: Traditionalist-authoritarian | G6: Socialism | H6: T/SOC | I6: Post-Marxist dominant-party developmentalism (MPLA) | J6: Nationalism | K6: Authoritarian rule; Developmentalism | L6: State authority; national development; market reform with state role; social conservatism; energy/resources; security | M6: C+/T — nationalist-developmental
A7: Antigua and Barbuda | B7: Charles III | C7: Gaston Browne | D7: Socialism | E7: S | F7: Social democracy | G7: Liberalism | H7: S/LIB | I7: Caribbean labourist social democracy (ABLP) | L7: Social-democratic Caribbean governance; market economy; tourism; moderate social policy | M7: L/C — centre-left
A8: Argentina | B8: Javier Milei | C8: Javier Milei | D8: Liberalism | E8: L+ | F8: National / populist liberalism | G8: Conservatism | H8: L+/CON | I8: Libertarian populism (Milei) | J8: Populism | L8: Radical market liberalisation; individual liberty; deregulation; reduced state; restrictive fiscal policy; socially mixed; strong Western alignment | M8: R — libertarian right, not primarily conservative
A9: Armenia | B9: Vahagn Khachaturyan | C9: Nikol Pashinyan | D9: Liberalism | E9: L | F9: Liberalism | H9: L | I9: Liberal-democratic reformism (Civil Contract) | L9: Market economy; democratic/institutional reform; secular social policy; security-focused foreign policy | M9: L/C — liberal-centrist
A10: Australia | B10: Charles III | C10: Anthony Albanese | D10: Socialism | E10: S | F10: Social democracy | G10: Liberalism | H10: S/LIB | I10: Social democracy (Labor) | J10: Ecologism | L10: Mixed economy; welfare state; multicultural migration; climate transition; alliance with US | M10: L — centre-left
A11: Austria | B11: Alexander Van der Bellen | C11: Christian Stocker | D11: Conservatism | E11: C | F11: Conservatism | G11: Socialism | H11: C/SOC | I11: Christian democracy (ÖVP-led coalition with SPÖ and NEOS) | L11: Market economy + social partnership; institutional continuity; controlled migration; pragmatic climate policy; EU/NATO-aligned security | M11: C — Christian-democratic conservative
A12: Azerbaijan | B12: Ilham Aliyev | C12: Ali Asadov | D12: Traditionalist-authoritarian | E12: T | F12: Traditionalist-authoritarian | H12: T | I12: Authoritarian state nationalism | J12: Nationalism | K12: Authoritarian rule | L12: National sovereignty; executive authority; traditional social order; hydrocarbons; restrictive migration; security-first foreign policy | M12: T — authoritarian-nationalist
A13: Bahamas | B13: Charles III | C13: Philip Davis | D13: Socialism | E13: S | F13: Social democracy | G13: Liberalism | H13: S/LIB | I13: Centre-left labourism (PLP) | L13: Social-democratic Caribbean model; tourism; moderate migration; climate/vulnerability policy | M13: L/C — centre-left
A14: Bahrain | B14: Hamad bin Isa Al Khalifa | C14: Salman bin Hamad Al Khalifa | D14: Conservatism | E14: Cm | F14: Monarchical traditionalism | G14: Religious-political ideology | H14: Cm/REL | I14: Sunni monarchical traditionalism | K14: Religion; Authoritarian rule | L14: Dynastic authority; Sunni-Islamic tradition; state-led development; controlled migration; energy diversification; security alignment | M14: T — monarchic traditionalist
A15: Bangladesh | B15: Mirza Fakhrul Islam Alamgir | C15: Tarique Rahman | D15: Conservatism | E15: C+ | F15: National / religious / populist conservatism | H15: C+ | I15: Bangladeshi-nationalist conservatism (BNP) | J15: Nationalism | K15: Religion | L15: National identity; religious/social conservatism; market economy with state role; migration/labour policy; security and sovereignty | M15: C+/N — conservative-nationalist hybrid
A16: Barbados | B16: Jeffrey Bostic | C16: Mia Mottley | D16: Socialism | E16: S | F16: Social democracy | H16: S | I16: Social democracy (BLP) | J16: Ecologism | L16: Social-democratic welfare; tourism; progressive social policy; climate resilience; multilateral foreign policy | M16: L — centre-left
A17: Belarus | B17: Alexander Lukashenko | C17: Alexander Turchin | D17: Traditionalist-authoritarian | E17: T | F17: Traditionalist-authoritarian | G17: Socialism | H17: T/SOC | I17: Authoritarian state paternalism with Soviet-nostalgic nationalism | J17: Nationalism | K17: Authoritarian rule | L17: State authority; social conservatism; state economy; restrictive migration; energy/security dependence; continuity | M17: T — authoritarian-traditionalist
A18: Belgium | B18: Philippe | C18: Bart De Wever | D18: Conservatism | E18: C+ | F18: National / religious / populist conservatism | H18: C+ | I18: Conservative Flemish nationalism (N-VA-led federal coalition) | J18: Nationalism | L18: Market economy; fiscal restraint; institutional order; stricter migration/integration; pragmatic climate/industry; NATO/EU | M18: C — national/Christian-democratic conservative
A19: Belize | B19: Charles III | C19: Johnny Briceño | D19: Socialism | E19: S | F19: Social democracy | G19: Liberalism | H19: S/LIB | I19: Centre-left (PUP) | L19: Mixed economy; social programmes; tourism; moderate migration; climate vulnerability | M19: L/C — centre-left
A20: Benin | B20: Romuald Wadagni | C20: Romuald Wadagni | D20: Liberalism | E20: L | F20: Liberalism | H20: L | I20: Technocratic market liberalism | K20: Developmentalism | L20: State capacity; economic development; market reform; order/security; infrastructure and regional security | M20: C+/T — developmental-conservative hybrid
A21: Bhutan | B21: Jigme Khesar Namgyel Wangchuck | C21: Tshering Tobgay | D21: Conservatism | E21: Cm | F21: Monarchical traditionalism | H21: Cm | I21: Buddhist monarchical traditionalism (Gross National Happiness) | J21: Ecologism | K21: Religion | L21: Monarchy and cultural continuity; regulated development; environmental stewardship; cautious social change | M21: T/C — monarchic-traditionalist
A22: Bolivia | B22: Rodrigo Paz | C22: Rodrigo Paz | D22: Liberalism | E22: L | F22: Liberalism | G22: Conservatism | H22: L/CON | I22: Centre-right market liberalism | L22: Market reform; decentralisation; security/order; moderate social conservatism; pragmatic foreign policy | M22: R — centre-right liberal
A23: Bosnia and Herzegovina | B23: Denis Bećirović / Željka Cvijanović / Željko Komšić | C23: Borjana Krišto | D23: Conservatism | E23: C+ | F23: National / religious / populist conservatism | G23: Socialism | H23: C+/SOC | I23: Consociational ethno-national conservatisms (divided presidency) | J23: Nationalism | K23: Religion | L23: Ethno-national and institutional interests; mixed economy; EU integration; migration/security; plural social positions | M23: L/C — fragmented coalition
A24: Botswana | B24: Duma Boko | C24: Duma Boko | D24: Socialism | E24: S | F24: Social democracy | G24: Liberalism | H24: S/LIB | I24: Centre-left (UDC) | L24: Social programmes; market economy; institutional democracy; mining; regional diplomacy | M24: L/C — centre-left
A25: Brazil | B25: Luiz Inácio Lula da Silva | C25: Luiz Inácio Lula da Silva | D25: Socialism | E25: S | F25: Social democracy | H25: S | I25: Democratic socialism / social democracy (PT) | J25: Ecologism | K25: Developmentalism | L25: Social welfare; developmental state; progressive social policy; environmental protection; multilateral diplomacy | M25: L — left
A26: Brunei | B26: Hassanal Bolkiah | C26: Hassanal Bolkiah | D26: Religious-political ideology | E26: RE+ | F26: Religious-national rule | G26: Conservatism | H26: RE+/CON | I26: Malay Islamic Monarchy (MIB) | J26: Nationalism | K26: Authoritarian rule | L26: Absolute monarchy; Malay-Islamic tradition; state/energy economy; restrictive social policy; controlled migration | M26: T — dynastic-religious traditionalist
A27: Bulgaria | B27: Iliana Iotova | C27: Rumen Radev | D27: Socialism | E27: S+ | F27: Left-nationalist / left-populist socialism | H27: S+ | I27: Sovereigntist left-populism (Radev) | J27: Nationalism; Populism | L27: National sovereignty; security; mixed economy; EU orientation; more restrictive migration; pragmatic energy policy | M27: C+/L — mixed centre-right/national
A28: Burkina Faso | B28: Ibrahim Traoré | C28: Jean Emmanuel Ouédraogo | D28: Socialism | E28: S+ | F28: Left-nationalist / left-populist socialism | H28: S+ | I28: Revolutionary military pan-Africanism (Sankarist) | J28: Nationalism; Populism | K28: Authoritarian rule | L28: National sovereignty; military authority; state-led development; traditional social order; restrictive external migration; anti-colonial foreign policy | M28: T — military-nationalist
A29: Burundi | B29: Évariste Ndayishimiye | C29: Nestor Ntahontuye | D29: Traditionalist-authoritarian | E29: T | F29: Traditionalist-authoritarian | H29: T | I29: Dominant-party authoritarianism (CNDD-FDD) | J29: Nationalism | K29: Religion; Authoritarian rule | L29: Executive authority; national unity; state-led development; socially conservative; security-first | M29: T/C — nationalist-authoritarian hybrid
A30: Cabo Verde | B30: José Maria Neves | C30: Francisco Carvalho | D30: Socialism | E30: S | F30: Social democracy | G30: Liberalism | H30: S/LIB | I30: Social democracy (PAICV) | L30: Democratic institutions; tourism/services; social policy; climate resilience; EU/Atlantic orientation | M30: L/C — centre-left/centrist
A31: Cambodia | B31: Norodom Sihamoni | C31: Hun Manet | D31: Traditionalist-authoritarian | E31: T | F31: Traditionalist-authoritarian | G31: Conservatism | H31: T/CON | I31: Dominant-party developmental authoritarianism (CPP) | J31: Nationalism | K31: Authoritarian rule; Developmentalism | L31: Monarchy/continuity; authority; state-led development; socially conservative; controlled migration; China/ASEAN balancing | M31: T/C — conservative-developmental
A32: Cameroon | B32: Paul Biya | C32: Joseph Ngute | D32: Traditionalist-authoritarian | E32: T | F32: Traditionalist-authoritarian | H32: T | I32: Personalist incumbency (CPDM) | K32: Authoritarian rule | L32: Executive continuity; state authority; traditional social order; resource economy; security | M32: T — authoritarian-traditionalist
A33: Canada | B33: Charles III | C33: Mark Carney | D33: Liberalism | E33: L | F33: Liberalism | H33: L | I33: Social liberalism (Liberal Party) | J33: Ecologism | L33: Market economy + welfare; multicultural migration; climate/industrial policy; Atlantic/NATO orientation | M33: L/C — liberal-centrist
A34: Central African Republic | B34: Faustin-Archange Touadéra | C34: Félix Moloua | D34: Traditionalist-authoritarian | E34: T | F34: Traditionalist-authoritarian | H34: T | I34: Personalist developmental authoritarianism | K34: Authoritarian rule | L34: Executive authority; state-led development; security; resource extraction; sovereignty | M34: T — authoritarian-developmental
A35: Chad | B35: Mahamat Déby | C35: Allamaye Halina | D35: Traditionalist-authoritarian | E35: T | F35: Traditionalist-authoritarian | H35: T | I35: Military-dynastic rule | J35: Nationalism | K35: Authoritarian rule | L35: Authority/order; security; state-led development; traditional social order; regional security | M35: T — military-nationalist
A36: Chile | B36: José Antonio Kast | C36: José Antonio Kast | D36: Conservatism | E36: C+ | F36: National / religious / populist conservatism | H36: C+ | I36: National conservatism (Kast) | J36: Nationalism | K36: Religion | L36: Traditional family/social order; law and order; private property/market economy; restrictive migration; energy pragmatism; security-oriented foreign policy | M36: C — national-conservative
A37: China | B37: Xi Jinping | C37: Li Qiang | D37: Socialism | E37: SM | F37: Marxism-Leninism | H37: SM | I37: Marxism-Leninism ('socialism with Chinese characteristics') | J37: Nationalism | K37: Authoritarian rule; Developmentalism | L37: Party authority; national continuity; state capitalism; social discipline; controlled migration; strategic autonomy | M37: T/R — communist-nationalist, not conservative in Freedenian sense
A38: Colombia | B38: Abelardo de la Espriella | C38: Abelardo de la Espriella | D38: Conservatism | E38: C+ | F38: National / religious / populist conservatism | H38: C+ | I38: National-conservative right (de la Espriella) | J38: Nationalism; Populism | L38: Security/order; market economy; traditional social values; restrictive migration; resource/energy development; strong US/security ties | M38: C+ — national-conservative
A39: Comoros | B39: Azali Assoumani | C39: Azali Assoumani | D39: Traditionalist-authoritarian | E39: T | F39: Traditionalist-authoritarian | G39: Religious-political ideology | H39: T/REL | I39: Presidential authoritarianism with Islamic social order | J39: Nationalism | K39: Religion; Authoritarian rule | L39: Executive authority; Islamic social order; state-led development; security; regional diplomacy | M39: T/C — presidential traditionalist
A40: Costa Rica | B40: Laura Fernández | C40: Laura Fernández | D40: Conservatism | E40: C+ | F40: National / religious / populist conservatism | G40: Liberalism | H40: C+/LIB | I40: Populist centre-right (Chaves continuity) | J40: Populism | L40: Security/order; market economy; fiscal reform; socially mixed; migration control; climate policy retained | M40: C+ — populist/centre-right hybrid
...

Sheet Summary
A1: Family | B1: States | C1: Share of states
A2: Liberalism | B2: =COUNTIF('195 States'!$D$2:$D$196,A2) | C2: =B2/$B$8
A3: Conservatism | B3: =COUNTIF('195 States'!$D$2:$D$196,A3) | C3: =B3/$B$8
A4: Socialism | B4: =COUNTIF('195 States'!$D$2:$D$196,A4) | C4: =B4/$B$8
A5: Religious-political ideology | B5: =COUNTIF('195 States'!$D$2:$D$196,A5) | C5: =B5/$B$8
A6: Traditionalist-authoritarian | B6: =COUNTIF('195 States'!$D$2:$D$196,A6) | C6: =B6/$B$8
A7: Total | B7: =SUM(B2:B6) | C7: =SUM(C2:C6)
A8: States in dataset | B8: =COUNTA('195 States'!$A$2:$A$196)
A10: Variant code | B10: Variant | C10: Family | D10: States | E10: Definition
A11: L | B11: Liberalism | C11: Liberalism | D11: =COUNTIF('195 States'!$E$2:$E$196,A11) | E11: Clear liberal morphology: social, market or centrist liberalism.
A12: L+ | B12: National / populist liberalism | C12: Liberalism | D12: =COUNTIF('195 States'!$E$2:$E$196,A12) | E12: Liberal core combined strongly with nationalism or populism.
A13: C | B13: Conservatism | C13: Conservatism | D13: =COUNTIF('195 States'!$E$2:$E$196,A13) | E13: Clear conservative morphology: Christian-democratic, liberal-conservative or customary conservatism.
A14: C+ | B14: National / religious / populist conservatism | C14: Conservatism | D14: =COUNTIF('195 States'!$E$2:$E$196,A14) | E14: Conservative core combined strongly with nationalism, populism, religion or authoritarianism.
A15: Cm | B15: Monarchical traditionalism | C15: Conservatism | D15: =COUNTIF('195 States'!$E$2:$E$196,A15) | E15: A ruling monarchy manages change from above to preserve a dynastic and often religious order.
A16: S | B16: Social democracy | C16: Socialism | D16: =COUNTIF('195 States'!$E$2:$E$196,A16) | E16: Social democracy or democratic socialism within a competitive democracy.
A17: S+ | B17: Left-nationalist / left-populist socialism | C17: Socialism | D17: =COUNTIF('195 States'!$E$2:$E$196,A17) | E17: Socialist core combined strongly with nationalism, populism or authoritarianism.
A18: SM | B18: Marxism-Leninism | C18: Socialism | D18: =COUNTIF('195 States'!$E$2:$E$196,A18) | E18: Communist party-state; the party's doctrine organises state and economy.
A19: RE | B19: Theocracy | C19: Religious-political ideology | D19: =COUNTIF('195 States'!$E$2:$E$196,A19) | E19: Religious doctrine and clerical authority define the state.
A20: RE+ | B20: Religious-national rule | C20: Religious-political ideology | D20: =COUNTIF('195 States'!$E$2:$E$196,A20) | E20: Religious legitimacy fused with dynastic or national authority.
A21: T | B21: Traditionalist-authoritarian | C21: Traditionalist-authoritarian | D21: =COUNTIF('195 States'!$E$2:$E$196,A21) | E21: Order, hierarchy and continuity without a sustained macro-ideology (military, personalist or dominant-party rule).
A22: Total | D22: =SUM(D11:D21)
A24: Component | B24: Type | D24: States
A25: Nationalism | B25: Thin-centred ideology | D25: =COUNTIF('195 States'!$J$2:$J$196,"*"&A25&"*")
A26: Populism | B26: Thin-centred ideology | D26: =COUNTIF('195 States'!$J$2:$J$196,"*"&A26&"*")
A27: Ecologism | B27: Thin-centred ideology | D27: =COUNTIF('195 States'!$J$2:$J$196,"*"&A27&"*")
A28: Feminism | B28: Thin-centred ideology | D28: =COUNTIF('195 States'!$J$2:$J$196,"*"&A28&"*")
A29: Religion | B29: Adjacent concept | D29: =COUNTIF('195 States'!$K$2:$K$196,"*"&A29&"*")
A30: Developmentalism | B30: Adjacent concept | D30: =COUNTIF('195 States'!$K$2:$K$196,"*"&A30&"*")
A31: Authoritarian rule | B31: Regime context (not an ideology) | D31: =COUNTIF('195 States'!$K$2:$K$196,"*"&A31&"*")

Sheet Methodology
A1: Field | B1: Definition / note
A2: Snapshot date | B2: 2026-10-03 (leaders as in the corrected conservatism dataset of the same date)
A3: Coverage | B3: 195 states: 193 UN members + Palestine + Vatican City. Country names follow UN short names.
A4: Leader source | B4: Wikipedia list of current heads of state and government (retrieved 2026-10-03), cross-checked against news reports. Unchanged from the source dataset.
A5: Framework | B5: Michael Freeden's morphological approach: an ideology is a configuration of core, adjacent and peripheral concepts, each 'decontested' (given one settled meaning). Families are identified by their core concepts, not by a left-right position or a checklist of policies. Each family appears in several decontested variants.
A6: Unit coded | B6: The governing ideology of the executive that actually directs policy (normally the head of government, or the head of state where executive power sits there). A ceremonial head of state does not determine the code.
A7: Ideological family | B7: The macro-ideology whose core concepts organise the government's programme: Liberalism, Conservatism, Socialism, plus Religious-political ideology and a residual Traditionalist-authoritarian category. Nationalism is never coded as the family: in Freeden's account it is thin-centred and needs a host, so it is recorded as a component (and signalled by "+" variants).
A8: Liberalism | B8: Core concepts (Freeden): liberty, rationality, individuality, progress, sociability, the general interest, and limited, accountable power.
A9: Conservatism | B9: Core concepts (Freeden): change must be controlled so that it appears natural and organic; social order has extra-human origins (history, God, nature, the market or monarchy) and is independent of human will.
A10: Socialism | B10: Core concepts (Freeden): the constitutive nature of the group, equality, human welfare as the goal of politics, human activity/praxis, and history as the arena of change.
A11: Religious-political ideology | B11: Political order is derived from religious doctrine and religious authority. Not one of Freeden's three macro-ideologies; included because his morphological method treats such belief systems as ideologies with their own core concepts (divine sovereignty, sacred law, clerical or dynastic-religious authority).
A12: Traditionalist-authoritarian | B12: Residual category, not a Freeden family: hierarchy, order, continuity and state authority dominate, but no liberal, conservative or socialist programme is sustained at the core. Typical of military, personalist and dominant-party regimes. Calling these conservative would overstate the presence of conservative morphology; nationalism usually appears as a component.
... A30: Caveat | B30: Codes are interpretive judgements for teaching and discussion, not measurements. Coalitions, caretaker and transitional governments are coded by their dominant governing morphology. The policy column is descriptive and unchanged from the source dataset.

Sheet Sources
A1: Use | B1: Source | C1: URL
A2: Current leaders | B2: UN Protocol & Liaison Service | C2: https://www.un.org/dgacm/en/content/protocol/hshgnfa
A3: Current leaders cross-check | B3: CIA World Leaders | C3: https://www.cia.gov/resources/world-leaders/
A4: Current heads list used for 2026 snapshot | B4: Wikipedia – List of current heads of state and government | C4: https://en.wikipedia.org/wiki/List_of_current_heads_of_state_and_government
A5: Freeden framework | B5: Stanford Encyclopedia of Philosophy – Conservatism | C5: https://seop.illc.uva.nl/entries/conservatism/
A6: Freeden framework | B6: Freeden, M. (1996) Ideologies and Political Theory: A Conceptual Approach. Oxford: Clarendon Press.
A7: Thin-centred nationalism | B7: Freeden, M. (1998) "Is Nationalism a Distinct Ideology?" Political Studies 46(4): 748-765. | C7: https://doi.org/10.1111/1467-9248.00165
A8: Freeden framework (introductory) | B8: Freeden, M. (2003) Ideology: A Very Short Introduction. Oxford: Oxford University Press.
A9: Families and variants | B9: Freeden, M., Sargent, L.T. and Stears, M. (eds) (2013) The Oxford Handbook of Political Ideologies. Oxford: Oxford University Press.
A10: Thin-centred populism | B10: Mudde, C. (2004) "The Populist Zeitgeist." Government and Opposition 39(4): 541-563. | C10: https://doi.org/10.1111/j.1477-7053.2004.00135.x

Sheet Change log
A1: Type | B1: Country | C1: Field | D1: Old value | E1: New value | F1: Reason
A2: Recoding | B2: All 195 states | C2: Classification | D2: Five families with nationalism as a possible primary family (LIB, CON, SOC, NAT, REL) | E2: Variants within each family (L, L+; C, C+, Cm; S, S+, SM; RE, RE+) plus residual T; nationalism only as a component | F2: Nationalism is thin-centred (Freeden 1998) and is not treated as a host ideology; variants show the range of decontested forms within each family, as C and C+ did in the conservatism scheme
A3: Recoding | B3: Algeria | C3: Classification | D3: NAT/SOC | E3: S+ | F3: Former NAT-primary state reassigned to the family whose core concepts it draws on, or to the residual T category
A4: Recoding | B4: Angola | C4: Classification | D4: NAT/SOC | E4: T/SOC | F4: Former NAT-primary state reassigned to the family whose core concepts it draws on, or to the residual T category
A5: Recoding | B5: Azerbaijan | C5: Classification | D5: NAT | E5: T | F5: Former NAT-primary state reassigned to the family whose core concepts it draws on, or to the residual T category
A6: Recoding | B6: Bangladesh | C6: Classification | D6: NAT/CON | E6: C+ | F6: Former NAT-primary state reassigned to the family whose core concepts it draws on, or to the residual T category
A7: Recoding | B7: Belarus | C7: Classification | D7: NAT/CON | E7: T/SOC | F7: Former NAT-primary state reassigned to the family whose core concepts it draws on, or to the residual T category
A8: Recoding | B8: Bosnia and Herzegovina | C8: Classification | D8: NAT/LIB | E8: C+/SOC | F8: Former NAT-primary state reassigned to the family whose core concepts it draws on, or to the residual T category
A9: Recoding | B9: Bulgaria | C9: Classification | D9: NAT/SOC | E9: S+ | F9: Former NAT-primary state reassigned to the family whose core concepts it draws on, or to the residual T category
A10: Recoding | B10: Burkina Faso | C10: Classification | D10: NAT/SOC | E10: S+ | F10: Former NAT-primary state reassigned to the family whose core concepts it draws on, or to the residual T category
A11: Recoding | B11: Burundi | C11: Classification | D11: NAT | E11: T | F11: Former NAT-primary state reassigned to the family whose core concepts it draws on, or to the residual T category
A12: Recoding | B12: Cambodia | C12: Classification | D12: NAT/CON | E12: T/CON | F12: Former NAT-primary state reassigned to the family whose core concepts it draws on, or to the residual T category
... A111: Naming | B111: Turkey | C111: Country | D111: Turkey | E111: Türkiye | F111: Use UN official short name
